<?xml version="1.0" ?>
<!-- =================================================================================== -->
<!-- |    This document was autogenerated by xacro from resource/xacro/bolt.urdf.xacro | -->
<!-- |    EDITING THIS FILE BY HAND IS NOT RECOMMENDED                                 | -->
<!-- =================================================================================== -->
<robot name="bolt" xmlns:controller="http://playerstage.sourceforge.net/gazebo/xmlschema/#controller" xmlns:interface="http://playerstage.sourceforge.net/gazebo/xmlschema/#interface" xmlns:sensor="http://playerstage.sourceforge.net/gazebo/xmlschema/#sensor">
  <!-- This file is based on: https://atlas.is.localnet/confluence/display/AMDW/Quadruped+URDF+Files -->
  <link name="base_link">
    <!-- BASE LINK INERTIAL -->
    <inertial>
      <origin rpy="0 0 0" xyz="-0.00245656 -0.00078880 0.03308090"/>
      <mass value="0.61436936"/>
      <!-- The base is extremely symmetrical. -->
      <!--inertia ixx="0.00578574" ixy="0.0" ixz="0.0"
                 iyy="0.01938108" iyz="0.0"
                 izz="0.02476124"
        /-->
      <inertia ixx="0.00132170" ixy="0.00000117" ixz="0.0" iyy="0.00144035" iyz="-0.00001139" izz="0.00198196"/>
    </inertial>
    <!-- BASE LINK VISUAL -->
    <visual>
      <origin rpy="0 0 0" xyz="0 0 0"/>
      <geometry>
        <mesh filename="package://robot_properties_bolt/meshes/stl/bolt_body.stl"/>
      </geometry>
      <material name="grey">
        <color rgba="0.8 0.8 0.8 1.0"/>
      </material>
    </visual>
    <!-- BASE LINK COLLISION -->
    <collision>
      <origin rpy="0 0 0" xyz="0 0 0"/>
      <geometry>
        <mesh filename="package://robot_properties_bolt/meshes/stl/bolt_body.stl"/>
      </geometry>
      <material name="grey">
        <color rgba="0.8 0.8 0.8 1.0"/>
      </material>
    </collision>
    <!-- Bullet specific paramters -->
    <contact>
      <lateral_friction value="1.0"/>
      <restitution value="0.5"/>
    </contact>
  </link>
  <!-- END BASE LINK -->
  <joint name="FL_HAA" type="revolute">
    <parent link="base_link"/>
    <child link="FL_SHOULDER"/>
    <limit effort="1000" lower="-10" upper="10" velocity="1000"/>
    <!-- joints rotates around the x-axis -->
    <axis xyz="1 0 0"/>
    <origin rpy="0 0 0" xyz="0.0 0.0636 0"/>
    <!-- pybullet simulation parameters -->
    <dynamics damping="0.0" friction="0.0"/>
  </joint>
  <link name="FL_SHOULDER">
    <!-- TODO: Update inertias and add visuals for link. -->
    <!-- create a dummy shoulder link to join the two joints -->
    <inertial>
      <!-- Left upper leg inertia -->
      <mass value="0.14004265"/>
      <origin rpy="0 0 0" xyz="0.01708256 -0.00446892 -0.01095830"/>
      <inertia ixx="0.00007443" ixy="0.00000148" ixz="0.00002154" iyy="0.00013847" iyz="-0.00001096" izz="0.00009002"/>
    </inertial>
    <!-- UPPER LEG LINK VISUAL -->
    <visual>
      <origin rpy="0 0 0" xyz="0 0 0"/>
      <geometry>
        <mesh filename="package://robot_properties_bolt/meshes/stl/bolt_hip_fe_left_side.stl"/>
      </geometry>
      <material name="grey">
        <color rgba="0.8 0.8 0.8 1.0"/>
      </material>
    </visual>
    <!-- UPPER LEG LINK COLLISION -->
    <collision>
      <origin rpy="0 0 0" xyz="0 0 0"/>
      <geometry>
        <mesh filename="package://robot_properties_bolt/meshes/stl/bolt_upper_leg_left_side.stl"/>
      </geometry>
      <material name="grey">
        <color rgba="0.8 0.8 0.8 1.0"/>
      </material>
    </collision>
    <!-- Bullet specific paramters -->
    <contact>
      <lateral_friction value="1.0"/>
      <restitution value="0.5"/>
    </contact>
  </link>
  <joint name="FL_HFE" type="revolute">
    <parent link="FL_SHOULDER"/>
    <child link="FL_UPPER_LEG"/>
    <limit effort="1000" lower="-10" upper="10" velocity="1000"/>
    <!-- joints rotates around the y-axis -->
    <axis xyz="0 1 0"/>
    <origin rpy="0 0 0" xyz="0 0.0145 -0.0386"/>
    <!-- pybullet simulation parameters -->
    <dynamics damping="0.0" friction="0.0"/>
  </joint>
  <link name="FL_UPPER_LEG">
    <!-- Left upper leg inertia -->
    <inertial>
      <origin rpy="0 0 0" xyz="0.00001377 0.01935853 -0.07870700"/>
      <mass value="0.14853845"/>
      <inertia ixx="0.00041107" ixy="0.00000000" ixz="0.00000009" iyy="0.00041193" iyz="-0.00004671" izz="0.00003024"/>
    </inertial>
    <!-- UPPER LEG LINK VISUAL -->
    <visual>
      <origin rpy="0 0 0" xyz="0 0 0"/>
      <geometry>
        <mesh filename="package://robot_properties_bolt/meshes/stl/bolt_upper_leg_left_side.stl"/>
      </geometry>
      <material name="grey">
        <color rgba="0.8 0.8 0.8 1.0"/>
      </material>
    </visual>
    <!-- UPPER LEG LINK COLLISION -->
    <collision>
      <origin rpy="0 0 0" xyz="0 0 0"/>
      <geometry>
        <mesh filename="package://robot_properties_bolt/meshes/stl/bolt_upper_leg_left_side.stl"/>
      </geometry>
      <material name="grey">
        <color rgba="0.8 0.8 0.8 1.0"/>
      </material>
    </collision>
    <!-- Bullet specific paramters -->
    <contact>
      <lateral_friction value="1.0"/>
      <restitution value="0.5"/>
    </contact>
  </link>
  <!-- END UPPER LEG LINK -->
  <!-- KFE: Joint between the upper leg and the lower leg -->
  <joint name="FL_KFE" type="revolute">
    <parent link="FL_UPPER_LEG"/>
    <child link="FL_LOWER_LEG"/>
    <limit effort="1000" lower="-10" upper="10" velocity="1000"/>
    <!-- joints rotates around the y-axis -->
    <axis xyz="0 1 0"/>
    <origin rpy="0 0 0" xyz="0 0.0374 -0.16"/>
    <!-- pybullet simulation parameters -->
    <dynamics damping="0.0" friction="0.0"/>
  </joint>
  <link name="FL_LOWER_LEG">
    <!-- Left lower leg inertia -->
    <inertial>
      <origin rpy="0 0 0" xyz="0.0 0.00836718 -0.09591877"/>
      <mass value="0.03117243"/>
      <inertia ixx="0.00011487" ixy="0.00000000" ixz="0.00000000" iyy="0.00011556" iyz="-0.00000190" izz="0.00000220"/>
    </inertial>
    <!-- LOWER LEG LINK VISUAL -->
    <visual>
      <origin rpy="0 0 0" xyz="0 0 0"/>
      <geometry>
        <mesh filename="package://robot_properties_bolt/meshes/stl/bolt_lower_leg_left_side.stl"/>
      </geometry>
      <material name="grey">
        <color rgba="0.8 0.8 0.8 1.0"/>
      </material>
    </visual>
    <!-- LOWER LEG LINK COLLISION -->
    <collision>
      <origin rpy="0 0 0" xyz="0 0 0"/>
      <geometry>
        <mesh filename="package://robot_properties_bolt/meshes/stl/bolt_lower_leg_left_side.stl"/>
      </geometry>
      <material name="grey">
        <color rgba="0.8 0.8 0.8 1.0"/>
      </material>
    </collision>
    <!-- Bullet specific paramters -->
    <contact>
      <lateral_friction value="1.0"/>
      <restitution value="0.5"/>
    </contact>
  </link>
  <!-- END LOWER LEG LINK -->
  <!-- KFE: Joint between the upper leg and the lower leg -->
  <joint name="FL_ANKLE" type="fixed">
    <parent link="FL_LOWER_LEG"/>
    <child link="FL_FOOT"/>
    <origin rpy="0 0 0" xyz="0 0.008 -0.16"/>
    <!-- Limits (usefull?) -->
    <limit effort="1000" lower="-10" upper="10" velocity="1000"/>
    <!-- pybullet simulation parameters -->
    <dynamics damping="0.0" friction="0.0"/>
  </joint>
  <link name="FL_FOOT">
    <!-- FOOT INERTIAL -->
    <!-- This link is symmetrical left or right -->
    <inertial>
      <origin rpy="0 0 0" xyz="0 0 0.00035767"/>
      <mass value="0.00000000"/>
      <inertia ixx="0.00000057" ixy="0.0" ixz="0.0" iyy="0.00000084" iyz="0.0" izz="0.00000053"/>
    </inertial>
    <!-- FOOT VISUAL -->
    <visual>
      <origin rpy="0 0 0" xyz="0 0 0"/>
      <geometry>
        <mesh filename="package://robot_properties_bolt/meshes/stl/bolt_foot.stl"/>
      </geometry>
      <material name="grey">
        <color rgba="0.8 0.8 0.8 1.0"/>
      </material>
    </visual>
    <!-- FOOT COLLISION -->
    <collision>
      <origin rpy="0 0 0" xyz="0 0 0"/>
      <geometry>
        <mesh filename="package://robot_properties_bolt/meshes/stl/bolt_foot.stl"/>
      </geometry>
      <material name="grey">
        <color rgba="0.8 0.8 0.8 1.0"/>
      </material>
    </collision>
    <!-- Bullet specific paramters -->
    <contact>
      <lateral_friction value="4.0"/>
      <restitution value="0.0"/>
    </contact>
  </link>
  <!-- END LOWER LEG LINK -->
  <joint name="FR_HAA" type="revolute">
    <parent link="base_link"/>
    <child link="FR_SHOULDER"/>
    <limit effort="1000" lower="-10" upper="10" velocity="1000"/>
    <!-- joints rotates around the x-axis -->
    <axis xyz="1 0 0"/>
    <origin rpy="0 0 0" xyz="0.0 -0.0636 0"/>
    <!-- pybullet simulation parameters -->
    <dynamics damping="0.0" friction="0.0"/>
  </joint>
  <link name="FR_SHOULDER">
    <!-- TODO: Update inertias and add visuals for link. -->
    <!-- create a dummy shoulder link to join the two joints -->
    <inertial>
      <!-- Right upper leg inertia -->
      <mass value="0.14004412"/>
      <origin rpy="0 0 0" xyz="0.01708233 0.00447099 -0.01095846"/>
      <inertia ixx="0.00007442" ixy="-0.00000148" ixz="0.00002154" iyy="0.00013848" iyz="0.00001095" izz="0.00009001"/>
    </inertial>
    <!-- UPPER LEG LINK VISUAL -->
    <visual>
      <origin rpy="0 0 0" xyz="0 0 0"/>
      <geometry>
        <mesh filename="package://robot_properties_bolt/meshes/stl/bolt_hip_fe_right_side.stl"/>
      </geometry>
      <material name="grey">
        <color rgba="0.8 0.8 0.8 1.0"/>
      </material>
    </visual>
    <!-- UPPER LEG LINK COLLISION -->
    <collision>
      <origin rpy="0 0 0" xyz="0 0 0"/>
      <geometry>
        <mesh filename="package://robot_properties_bolt/meshes/stl/bolt_upper_leg_right_side.stl"/>
      </geometry>
      <material name="grey">
        <color rgba="0.8 0.8 0.8 1.0"/>
      </material>
    </collision>
    <!-- Bullet specific paramters -->
    <contact>
      <lateral_friction value="1.0"/>
      <restitution value="0.5"/>
    </contact>
  </link>
  <joint name="FR_HFE" type="revolute">
    <parent link="FR_SHOULDER"/>
    <child link="FR_UPPER_LEG"/>
    <limit effort="1000" lower="-10" upper="10" velocity="1000"/>
    <!-- joints rotates around the y-axis -->
    <axis xyz="0 1 0"/>
    <origin rpy="0 0 0" xyz="0 -0.0145 -0.0386"/>
    <!-- pybullet simulation parameters -->
    <dynamics damping="0.0" friction="0.0"/>
  </joint>
  <link name="FR_UPPER_LEG">
    <!-- Right upper leg inertia -->
    <inertial>
      <origin rpy="0 0 0" xyz="-0.00001377 -0.01935853 -0.07870700"/>
      <mass value="0.14853845"/>
      <inertia ixx="0.00041107" ixy="0.00000000" ixz="-0.00000009" iyy="0.00041193" iyz="0.00004671" izz="0.00003024"/>
    </inertial>
    <!-- UPPER LEG LINK VISUAL -->
    <visual>
      <origin rpy="0 0 0" xyz="0 0 0"/>
      <geometry>
        <mesh filename="package://robot_properties_bolt/meshes/stl/bolt_upper_leg_right_side.stl"/>
      </geometry>
      <material name="grey">
        <color rgba="0.8 0.8 0.8 1.0"/>
      </material>
    </visual>
    <!-- UPPER LEG LINK COLLISION -->
    <collision>
      <origin rpy="0 0 0" xyz="0 0 0"/>
      <geometry>
        <mesh filename="package://robot_properties_bolt/meshes/stl/bolt_upper_leg_right_side.stl"/>
      </geometry>
      <material name="grey">
        <color rgba="0.8 0.8 0.8 1.0"/>
      </material>
    </collision>
    <!-- Bullet specific paramters -->
    <contact>
      <lateral_friction value="1.0"/>
      <restitution value="0.5"/>
    </contact>
  </link>
  <!-- END UPPER LEG LINK -->
  <!-- KFE: Joint between the upper leg and the lower leg -->
  <joint name="FR_KFE" type="revolute">
    <parent link="FR_UPPER_LEG"/>
    <child link="FR_LOWER_LEG"/>
    <limit effort="1000" lower="-10" upper="10" velocity="1000"/>
    <!-- joints rotates around the y-axis -->
    <axis xyz="0 1 0"/>
    <origin rpy="0 0 0" xyz="0 -0.0374 -0.16"/>
    <!-- pybullet simulation parameters -->
    <dynamics damping="0.0" friction="0.0"/>
  </joint>
  <link name="FR_LOWER_LEG">
    <!-- Right lower leg inertia -->
    <inertial>
      <origin rpy="0 0 0" xyz="0.0 -0.00836718 -0.09591877"/>
      <mass value="0.03117243"/>
      <inertia ixx="0.00011487" ixy="0.00000000" ixz="0.00000000" iyy="0.00011556" iyz="0.00000190" izz="0.00000220"/>
    </inertial>
    <!-- LOWER LEG LINK VISUAL -->
    <visual>
      <origin rpy="0 0 0" xyz="0 0 0"/>
      <geometry>
        <mesh filename="package://robot_properties_bolt/meshes/stl/bolt_lower_leg_right_side.stl"/>
      </geometry>
      <material name="grey">
        <color rgba="0.8 0.8 0.8 1.0"/>
      </material>
    </visual>
    <!-- LOWER LEG LINK COLLISION -->
    <collision>
      <origin rpy="0 0 0" xyz="0 0 0"/>
      <geometry>
        <mesh filename="package://robot_properties_bolt/meshes/stl/bolt_lower_leg_right_side.stl"/>
      </geometry>
      <material name="grey">
        <color rgba="0.8 0.8 0.8 1.0"/>
      </material>
    </collision>
    <!-- Bullet specific paramters -->
    <contact>
      <lateral_friction value="1.0"/>
      <restitution value="0.5"/>
    </contact>
  </link>
  <!-- END LOWER LEG LINK -->
  <!-- KFE: Joint between the upper leg and the lower leg -->
  <joint name="FR_ANKLE" type="fixed">
    <parent link="FR_LOWER_LEG"/>
    <child link="FR_FOOT"/>
    <origin rpy="0 0 0" xyz="0 -0.008 -0.16"/>
    <!-- Limits (usefull?) -->
    <limit effort="1000" lower="-10" upper="10" velocity="1000"/>
    <!-- pybullet simulation parameters -->
    <dynamics damping="0.0" friction="0.0"/>
  </joint>
  <link name="FR_FOOT">
    <!-- FOOT INERTIAL -->
    <!-- This link is symmetrical left or right -->
    <inertial>
      <origin rpy="0 0 0" xyz="0 0 0.00035767"/>
      <mass value="0.00000000"/>
      <inertia ixx="0.00000057" ixy="0.0" ixz="0.0" iyy="0.00000084" iyz="0.0" izz="0.00000053"/>
    </inertial>
    <!-- FOOT VISUAL -->
    <visual>
      <origin rpy="0 0 0" xyz="0 0 0"/>
      <geometry>
        <mesh filename="package://robot_properties_bolt/meshes/stl/bolt_foot.stl"/>
      </geometry>
      <material name="grey">
        <color rgba="0.8 0.8 0.8 1.0"/>
      </material>
    </visual>
    <!-- FOOT COLLISION -->
    <collision>
      <origin rpy="0 0 0" xyz="0 0 0"/>
      <geometry>
        <mesh filename="package://robot_properties_bolt/meshes/stl/bolt_foot.stl"/>
      </geometry>
      <material name="grey">
        <color rgba="0.8 0.8 0.8 1.0"/>
      </material>
    </collision>
    <!-- Bullet specific paramters -->
    <contact>
      <lateral_friction value="4.0"/>
      <restitution value="0.0"/>
    </contact>
  </link>
  <!-- END LOWER LEG LINK -->
</robot>
